<mujoco model="tendon">
	
	
    <actuator>
	<motor name="robot0_torq_j1" joint="robot0_joint_1" ctrlrange="0 1" ctrllimited="true" gear="20 0" />
	<motor name="robot0_torq_j2" joint="robot0_joint_2" ctrlrange="0 1" ctrllimited="true" gear="20 0" />
	<motor name="robot0_torq_j3" joint="robot0_joint_3" ctrlrange="0 1" ctrllimited="true" gear="20 0" />
	<motor name="robot0_torq_j4" joint="robot0_joint_4" ctrlrange="0 1" ctrllimited="true" gear="20 0" />
	<motor name="robot0_torq_j5" joint="robot0_joint_5" ctrlrange="0 1" ctrllimited="true" gear="20 0" />
	<motor name="robot0_torq_j6" joint="robot0_joint_6" ctrlrange="0 1" ctrllimited="true" gear="20 0" />
    </actuator>


	<asset>
		<mesh name="robot0_base" file="/home/john/Desktop/robotic-ultrasound-imaging/robosuite/robosuite/models/assets/robots/tendon/./meshes/base.STL" scale="1 1 1" />
		<mesh name="robot0_s1" file="/home/john/Desktop/robotic-ultrasound-imaging/robosuite/robosuite/models/assets/robots/tendon/./meshes/s1.STL" scale="1 1 1" />
		<mesh name="robot0_s2" file="/home/john/Desktop/robotic-ultrasound-imaging/robosuite/robosuite/models/assets/robots/tendon/./meshes/s1.STL" scale="1 1 1" />
		<mesh name="robot0_s3" file="/home/john/Desktop/robotic-ultrasound-imaging/robosuite/robosuite/models/assets/robots/tendon/./meshes/s1.STL" scale="1 1 1" />
		<mesh name="robot0_s4" file="/home/john/Desktop/robotic-ultrasound-imaging/robosuite/robosuite/models/assets/robots/tendon/./meshes/s1.STL" scale="1 1 1" />
		<mesh name="robot0_s5" file="/home/john/Desktop/robotic-ultrasound-imaging/robosuite/robosuite/models/assets/robots/tendon/./meshes/s1.STL" scale="1 1 1" />
		<mesh name="robot0_s6" file="/home/john/Desktop/robotic-ultrasound-imaging/robosuite/robosuite/models/assets/robots/tendon/./meshes/s1.STL" scale="1 1 1" />
		<mesh name="robot0_s7" file="/home/john/Desktop/robotic-ultrasound-imaging/robosuite/robosuite/models/assets/robots/tendon/./meshes/s1.STL" scale="1 1 1" />
		<mesh name="robot0_s8" file="/home/john/Desktop/robotic-ultrasound-imaging/robosuite/robosuite/models/assets/robots/tendon/./meshes/s1.STL" scale="1 1 1" />
		<mesh name="robot0_s9" file="/home/john/Desktop/robotic-ultrasound-imaging/robosuite/robosuite/models/assets/robots/tendon/./meshes/s1.STL" scale="1 1 1" />
		<mesh name="robot0_s10" file="/home/john/Desktop/robotic-ultrasound-imaging/robosuite/robosuite/models/assets/robots/tendon/./meshes/s1.STL" scale="1 1 1" />
		
	</asset>





    <option timestep="0.002" tolerance="1e-10" jacobian="dense" gravity="0 0 -0.981" /> 

    


    <worldbody>
		<camera mode="fixed" name="robot0_default_camera" pos="-0.275 -1.079 1.497" xyaxes="0.998 0.068 -0.000 0.002 -0.024 1.000" />
		
		<site name="robot0_waypoint" type="sphere" size="0.001" pos="-1 -1 -1" rgba=".8 .8 .8 1" />



    	<body name="robot0_base" pos="-0.39 0.0 1.47" quat="0.0 0.70711 0.0 0.70711">
			
			
			<camera mode="fixed" pos="-0.25 -0.6 0.2" quat="0.61237244 0.35355339 -0.61237244 0.35355339" />
			
			<geom mesh="robot0_base" pos="0.0000 0.0000 0.0000" density="0.1" type="mesh" group="1" />

			<inertial diaginertia="0 0 0" mass="100" pos="0.05 0  -0.1" />

			
			<body>
				<geom type="sphere" pos="0.02028   0.00544 -0.15" size="0.005" rgba="0 0.5 0 1" />
				<joint name="robot0_joint_1" type="slide" axis="0 0 -1" damping="0.1" group="1" limited="true" range="-.1 .1" />
				<site name="robot0_end_1" pos="0.02028   0.00544 -0.15" />
			</body>

			<body>
				<geom type="sphere" pos="0.02028  -0.00544 -0.15" size="0.005" rgba="0 0.5 0 1" />
				<joint name="robot0_joint_2" type="slide" axis="0 0 -1" damping="0.1" group="1" limited="true" range="-.1 .1" />
				<site name="robot0_end_2" pos="0.02028  -0.00544 -0.15" />
			</body>

			<body>
				<geom type="sphere" pos="-0.00544 -0.02028 -0.15" size="0.005" rgba="0 0.5 0 1" />
				<joint name="robot0_joint_3" type="slide" axis="0 0 -1" damping="0.1" limited="true" range="-.1 .1" />
				<site name="robot0_end_3" pos="-0.00544 -0.02028 -0.15" />
			</body>

			<body>
				<geom type="sphere" pos="-0.01485 -0.01485 -0.15" size="0.005" rgba="0 0.5 0 1" />
				<joint name="robot0_joint_4" type="slide" axis="0 0 -1" damping="0.1" limited="true" range="-.1 .1" />
				<site name="robot0_end_4" pos="-0.01485 -0.01485 -0.15" />
			</body>

			<body>
				<geom type="sphere" pos="-0.01485  0.01485 -0.15" size="0.005" rgba="0 0.5 0 1" />
				<joint name="robot0_joint_5" type="slide" axis="0 0 -1" damping="0.1" limited="true" range="-.1 .1" />
				<site name="robot0_end_5" pos="-0.01485  0.01485 -0.15" />
			</body>

			<body>
				<geom type="sphere" pos="-0.00544  0.02028 -0.15" size="0.005" rgba="0 0.5 0 1" />
				<joint name="robot0_joint_6" type="slide" axis="0 0 -1" damping="0.1" limited="true" range="-.1 .1" />
				<site name="robot0_end_6" pos="-0.00544  0.02028 -0.15" />
			</body>

			
			<body name="robot0_s1">
			<geom type="sphere" pos="0 0 0.0000" size="0.005" rgba="0 0.5 0 1" />
			<joint type="hinge" pos="0 0 0.0000" axis="1 0 0" damping="0.9000" stiffness="0.35" />
			<joint type="hinge" pos="0 0 0.0000" axis="0 1 0" damping="0.9000" stiffness="0.35" />
			<geom mesh="robot0_s1" pos="0 0.0000 0.0000" density="0.1" type="mesh" group="1" name="robot0_s1_vis" />
			<geom mesh="robot0_s1" pos="0 0.0000 0.0000" density="0.1" type="mesh" group="0" name="robot0_s1_col" contype="1" conaffinity="1" rgba="0 0.5 0 1" />
			<site name="robot0_s_1_1" pos="0.02028   0.00544  -0.0000" size="0.002" />
			<site name="robot0_s_1_2" pos="0.02028  -0.00544  -0.0000" size="0.002" />
			<site name="robot0_s_1_3" pos="-0.00544 -0.02028  -0.0000" size="0.002" />
			<site name="robot0_s_1_4" pos="-0.01485 -0.01485  -0.0000" size="0.002" />
			<site name="robot0_s_1_5" pos="-0.01485  0.01485  -0.0000" size="0.002" />
			<site name="robot0_s_1_6" pos="-0.00544  0.02028  -0.0000" size="0.002" />	


			<body name="robot0_s2">
			<geom type="sphere" pos="0 0 0.050" size="0.005" rgba="0 0.5 0 1" />
			<joint type="hinge" pos="0 0 0.050" axis="1 0 0" damping="0.9000" stiffness="0.35" />
			<joint type="hinge" pos="0 0 0.050" axis="0 1 0" damping="0.9000" stiffness="0.35" />
			<geom mesh="robot0_s2" pos="0 0.0000 0.050" density="0.1" type="mesh" group="1" name="robot0_s2_vis" />
			<geom mesh="robot0_s2" pos="0 0.0000 0.050" density="0.1" type="mesh" group="0" name="robot0_s2_col" contype="1" conaffinity="1" rgba="0 0.5 0 1" />
			<site name="robot0_s_2_1" pos="0.02028   0.00544  0.0500" size="0.002" />
			<site name="robot0_s_2_2" pos="0.02028  -0.00544  0.0500" size="0.002" />
			<site name="robot0_s_2_3" pos="-0.00544 -0.02028  0.0500" size="0.002" />
			<site name="robot0_s_2_4" pos="-0.01485 -0.01485  0.0500" size="0.002" />
			<site name="robot0_s_2_5" pos="-0.01485  0.01485  0.0500" size="0.002" />
			<site name="robot0_s_2_6" pos="-0.00544  0.02028  0.0500" size="0.002" />
			
			
			<body name="robot0_s3">
			<geom type="sphere" pos="0 0 0.100" size="0.005" rgba="0 0.5 0 1" />
			<joint type="hinge" pos="0 0 0.100" axis="1 0 0" damping="0.9000" stiffness="0.35" />
			<joint type="hinge" pos="0 0 0.100" axis="0 1 0" damping="0.9000" stiffness="0.35" />
			<geom mesh="robot0_s3" pos="0 0.0000 0.100" density="0.1" type="mesh" group="1" name="robot0_s3_vis" />
			<geom mesh="robot0_s3" pos="0 0.0000 0.100" density="0.1" type="mesh" group="0" name="robot0_s3_col" contype="1" conaffinity="1" rgba="0 0.5 0 1" />
			<site name="robot0_s_3_1" pos="0.02028   0.00544  0.1000" size="0.002" />
			<site name="robot0_s_3_2" pos="0.02028  -0.00544  0.1000" size="0.002" />
			<site name="robot0_s_3_3" pos="-0.00544 -0.02028  0.1000" size="0.002" />
			<site name="robot0_s_3_4" pos="-0.01485 -0.01485  0.1000" size="0.002" />
			<site name="robot0_s_3_5" pos="-0.01485  0.01485  0.1000" size="0.002" />
			<site name="robot0_s_3_6" pos="-0.00544  0.02028  0.1000" size="0.002" />
			
			<body name="robot0_s4">
			<geom type="sphere" pos="0 0 0.150" size="0.005" rgba="0 0.5 0 1" />
			<joint type="hinge" pos="0 0 0.150" axis="1 0 0" damping="0.9000" stiffness="0.35" />
			<joint type="hinge" pos="0 0 0.150" axis="0 1 0" damping="0.9000" stiffness="0.35" />
			<geom mesh="robot0_s4" pos="0 0.0000 0.150" density="0.1" type="mesh" group="1" name="robot0_s4_vis" />
			<geom mesh="robot0_s4" pos="0 0.0000 0.150" density="0.1" type="mesh" group="0" name="robot0_s4_col" contype="1" conaffinity="1" rgba="0 0.5 0 1" />
			<site name="robot0_s_4_1" pos="0.02028   0.00544  0.1500" size="0.002" />
			<site name="robot0_s_4_2" pos="0.02028  -0.00544  0.1500" size="0.002" />
			<site name="robot0_s_4_3" pos="-0.00544 -0.02028  0.1500" size="0.002" />
			<site name="robot0_s_4_4" pos="-0.01485 -0.01485  0.1500" size="0.002" />
			<site name="robot0_s_4_5" pos="-0.01485  0.01485  0.1500" size="0.002" />
			<site name="robot0_s_4_6" pos="-0.00544  0.02028  0.1500" size="0.002" />
			
			<body name="robot0_s5">
			<geom type="sphere" pos="0 0 0.200" size="0.005" rgba="0 0.5 0 1" />
			<joint type="hinge" pos="0 0 0.200" axis="1 0 0" damping="0.9000" stiffness="0.35" />
			<joint type="hinge" pos="0 0 0.200" axis="0 1 0" damping="0.9000" stiffness="0.35" />
			<geom mesh="robot0_s5" pos="0 0.0000 0.200" density="0.1" type="mesh" group="1" name="robot0_s5_vis" />
			<geom mesh="robot0_s5" pos="0 0.0000 0.200" density="0.1" type="mesh" group="0" name="robot0_s5_col" contype="1" conaffinity="1" rgba="0 0.5 0 1" />
			<site name="robot0_s_5_1" pos="0.02028   0.00544  0.2000" size="0.002" />
			<site name="robot0_s_5_2" pos="0.02028  -0.00544  0.2000" size="0.002" />
			<site name="robot0_s_5_3" pos="-0.00544 -0.02028  0.2000" size="0.002" />
			<site name="robot0_s_5_4" pos="-0.01485 -0.01485  0.2000" size="0.002" />
			<site name="robot0_s_5_5" pos="-0.01485  0.01485  0.2000" size="0.002" />
			<site name="robot0_s_5_6" pos="-0.00544  0.02028  0.2000" size="0.002" />
			
			<body name="robot0_s6">
			<geom type="sphere" pos="0 0 0.250" size="0.005" rgba="0 0.5 0 1" />
			<joint type="hinge" pos="0 0 0.250" axis="1 0 0" damping="0.9000" stiffness="0.35" />
			<joint type="hinge" pos="0 0 0.250" axis="0 1 0" damping="0.9000" stiffness="0.35" />
			<geom mesh="robot0_s6" pos="0 0.0000 0.250" density="0.1" type="mesh" group="1" name="robot0_s6_vis" />
			<geom mesh="robot0_s6" pos="0 0.0000 0.250" density="0.1" type="mesh" group="0" name="robot0_s6_col" contype="1" conaffinity="1" rgba="0 0.5 0 1" />
			<site name="robot0_s_6_1" pos="0.02028   0.00544  0.2500" size="0.002" />
			<site name="robot0_s_6_2" pos="0.02028  -0.00544  0.2500" size="0.002" />
			<site name="robot0_s_6_3" pos="-0.00544 -0.02028  0.2500" size="0.002" />
			<site name="robot0_s_6_4" pos="-0.01485 -0.01485  0.2500" size="0.002" />
			<site name="robot0_s_6_5" pos="-0.01485  0.01485  0.2500" size="0.002" />
			<site name="robot0_s_6_6" pos="-0.00544  0.02028  0.2500" size="0.002" />

			<body name="robot0_s7">
			<geom type="sphere" pos="0 0 0.300" size="0.005" rgba="0 0.5 0 1" />
			<joint type="hinge" pos="0 0 0.300" axis="1 0 0" damping="0.9000" stiffness="0.35" />
			<joint type="hinge" pos="0 0 0.300" axis="0 1 0" damping="0.9000" stiffness="0.35" />
			<geom mesh="robot0_s7" pos="0 0.0000 0.300" density="0.1" type="mesh" group="1" name="robot0_s7_vis" />
			<geom mesh="robot0_s7" pos="0 0.0000 0.300" density="0.1" type="mesh" group="0" name="robot0_s7_col" contype="1" conaffinity="1" rgba="0 0.5 0 1" />
			<site name="robot0_s_7_1" pos="0.02028   0.00544  0.3000" size="0.002" />
			<site name="robot0_s_7_2" pos="0.02028  -0.00544  0.3000" size="0.002" />
			<site name="robot0_s_7_3" pos="-0.00544 -0.02028  0.3000" size="0.002" />
			<site name="robot0_s_7_4" pos="-0.01485 -0.01485  0.3000" size="0.002" />
			<site name="robot0_s_7_5" pos="-0.01485  0.01485  0.3000" size="0.002" />
			<site name="robot0_s_7_6" pos="-0.00544  0.02028  0.3000" size="0.002" />


			<body name="robot0_s8">
			<geom type="sphere" pos="0 0 0.350" size="0.005" rgba="0 0.5 0 1" />
			<joint type="hinge" pos="0 0 0.350" axis="1 0 0" damping="0.9000" stiffness="0.35" />
			<joint type="hinge" pos="0 0 0.350" axis="0 1 0" damping="0.9000" stiffness="0.35" />
			<geom mesh="robot0_s8" pos="0 0.0000 0.350" density="0.1" type="mesh" group="1" name="robot0_s8_vis" />
			<geom mesh="robot0_s8" pos="0 0.0000 0.350" density="0.1" type="mesh" group="0" name="robot0_s8_col" contype="1" conaffinity="1" rgba="0 0.5 0 1" />
			<site name="robot0_s_8_1" pos="0.02028   0.00544  0.3500" size="0.002" />
			<site name="robot0_s_8_2" pos="0.02028  -0.00544  0.3500" size="0.002" />
			<site name="robot0_s_8_3" pos="-0.00544 -0.02028  0.3500" size="0.002" />
			<site name="robot0_s_8_4" pos="-0.01485 -0.01485  0.3500" size="0.002" />
			<site name="robot0_s_8_5" pos="-0.01485  0.01485  0.3500" size="0.002" />
			<site name="robot0_s_8_6" pos="-0.00544  0.02028  0.3500" size="0.002" />


			<body name="robot0_s9">
			<geom type="sphere" pos="0 0 0.400" size="0.005" rgba="0 0.5 0 1" />
			<joint type="hinge" pos="0 0 0.400" axis="1 0 0" damping="0.9000" stiffness="0.35" />
			<joint type="hinge" pos="0 0 0.400" axis="0 1 0" damping="0.9000" stiffness="0.35" />
			<geom mesh="robot0_s9" pos="0 0.0000 0.400" density="0.1" type="mesh" group="1" name="robot0_s9_vis" />
			<geom mesh="robot0_s9" pos="0 0.0000 0.400" density="0.1" type="mesh" group="0" name="robot0_s9_col" contype="1" conaffinity="1" rgba="0 0.5 0 1" />
			<site name="robot0_s_9_1" pos="0.02028   0.00544  0.4000" size="0.002" />
			<site name="robot0_s_9_2" pos="0.02028  -0.00544  0.4000" size="0.002" />
			<site name="robot0_s_9_3" pos="-0.00544 -0.02028  0.4000" size="0.002" />
			<site name="robot0_s_9_4" pos="-0.01485 -0.01485  0.4000" size="0.002" />
			<site name="robot0_s_9_5" pos="-0.01485  0.01485  0.4000" size="0.002" />
			<site name="robot0_s_9_6" pos="-0.00544  0.02028  0.4000" size="0.002" />

			<body name="robot0_s10">
			<geom type="sphere" pos="0 0 0.450" size="0.005" rgba="0 0.5 0 1" />
			<joint type="hinge" pos="0 0 0.450" axis="1 0 0" damping="0.9000" stiffness="0.35" />
			<joint type="hinge" pos="0 0 0.450" axis="0 1 0" damping="0.9000" stiffness="0.35" />
			<geom mesh="robot0_s10" pos="0 0.0000 0.450" density="0.1" type="mesh" group="1" name="robot0_s10_vis" />
			<geom mesh="robot0_s10" pos="0 0.0000 0.450" density="0.1" type="mesh" group="0" name="robot0_s10_col" contype="1" conaffinity="1" rgba="0 0.5 0 1" />
			<site name="robot0_s_10_1" pos="0.02028   0.00544  0.4500" size="0.002" />
			<site name="robot0_s_10_2" pos="0.02028  -0.00544  0.4500" size="0.002" />
			<site name="robot0_s_10_3" pos="-0.00544 -0.02028  0.4500" size="0.002" />
			<site name="robot0_s_10_4" pos="-0.01485 -0.01485  0.4500" size="0.002" />
			<site name="robot0_s_10_5" pos="-0.01485  0.01485  0.4500" size="0.002" />
			<site name="robot0_s_10_6" pos="-0.00544  0.02028  0.4500" size="0.002" />


			
			
			<body name="robot0_right_hand" pos="0 0 0.50" quat="1 0 0 0">			
				<geom type="sphere" pos="0 0 0.50" size="0.005" rgba="0 0.5 0 1" />

				
				
				
				<site name="robot0_ee" pos="0 0 0" size="0.01 0.01 0.01" rgba="0 0 1 1" type="sphere" group="1" />
				<site name="robot0_ee_x" pos="0 0 0" size="0.005 .1" rgba="1 0 0 0" type="cylinder" group="1" />
				<site name="robot0_ee_z" pos="0 0 0" size="0.005 .1" rgba="0 0 1 0" type="cylinder" group="1" />
				<site name="robot0_ee_y" pos="0 0 0" size="0.005 .1" rgba="0 1 0 0" type="cylinder" group="1" />
				
				<camera mode="fixed" name="robot0_eye_in_hand" pos="0.05 0 0" quat="0 0.707108 0.707108 0" fovy="75" />
				
			</body>
			</body>
			</body>
			</body>
			</body>
			</body>
			</body>
			</body>
			</body>
			</body>
			</body>
		</body>
		</worldbody>
	
    <tendon>
		<spatial width="0.002" limited="true" range="0.20 0.30">
		<site site="robot0_end_1" />
		<site site="robot0_s_1_1" />
		<site site="robot0_s_2_1" />
		<site site="robot0_s_3_1" />
		<site site="robot0_s_4_1" />
		<site site="robot0_s_5_1" />
        </spatial>

		<spatial width="0.002" limited="true" range="0.46 0.56">
		<site site="robot0_end_2" />
		<site site="robot0_s_1_2" />
		<site site="robot0_s_2_2" />
		<site site="robot0_s_3_2" />
		<site site="robot0_s_4_2" />
		<site site="robot0_s_5_2" />
		<site site="robot0_s_6_2" />
		<site site="robot0_s_7_2" />
		<site site="robot0_s_8_2" />
		<site site="robot0_s_9_2" />
		<site site="robot0_s_10_2" />
        </spatial>


		<spatial width="0.002" limited="true" range="0.20 0.30">
		<site site="robot0_end_3" />
		<site site="robot0_s_1_3" />
		<site site="robot0_s_2_3" />
		<site site="robot0_s_3_3" />
		<site site="robot0_s_4_3" />
		<site site="robot0_s_5_3" />
		
		
		
        </spatial>


		<spatial width="0.002" limited="true" range="0.46 0.56">
		<site site="robot0_end_4" />
		<site site="robot0_s_1_4" />
		<site site="robot0_s_2_4" />
		<site site="robot0_s_3_4" />
		<site site="robot0_s_4_4" />
		<site site="robot0_s_5_4" />
		<site site="robot0_s_6_4" />
		<site site="robot0_s_7_4" />
		<site site="robot0_s_8_4" />
		<site site="robot0_s_9_4" />
		<site site="robot0_s_10_4" />
		
		
        </spatial>

		<spatial width="0.002" limited="true" range="0.20 0.30">
		<site site="robot0_end_5" />
		<site site="robot0_s_1_5" />
		<site site="robot0_s_2_5" />
		<site site="robot0_s_3_5" />
		<site site="robot0_s_4_5" />
		<site site="robot0_s_5_5" />
		
		
		
        </spatial>


		<spatial width="0.002" limited="true" range="0.46 0.56">
		<site site="robot0_end_6" />
		<site site="robot0_s_1_6" />
		<site site="robot0_s_2_6" />
		<site site="robot0_s_3_6" />
		<site site="robot0_s_4_6" />
		<site site="robot0_s_5_6" />
		<site site="robot0_s_6_6" />
		<site site="robot0_s_7_6" />
		<site site="robot0_s_8_6" />
		<site site="robot0_s_9_6" />
		<site site="robot0_s_10_6" />
		
        </spatial>		
    </tendon>


<sensor /><equality /><contact /><default /></mujoco>